{"uid":"8c36b0655a7799a3","name":"Valid login to katalon-demo-cura application -- @1.1 ","fullName":"User Login to katalon-demo-cura application: Valid login to katalon-demo-cura application","historyId":"e83a6604cc6352825a2b4b2f8b5425cb","time":{"start":1727098642140,"stop":1727098643487,"duration":1347},"status":"broken","statusMessage":"urllib3.exceptions.MaxRetryError: HTTPConnectionPool(host='localhost', port=48239): Max retries exceeded with url: /session/182ed2b93db7bbf3748c69ce5ef84bff/screenshot (Caused by NewConnectionError('<urllib3.connection.HTTPConnection object at 0x7f2823456af0>: Failed to establish a new connection: [Errno 111] Connection refused'))\n","statusTrace":"  File \"/opt/hostedtoolcache/Python/3.9.20/x64/lib/python3.9/site-packages/behave/runner.py\", line 545, in run_hook\n    self.hooks[name](context, *args)\n  File \"features/environment.py\", line 50, in after_step\n    context.driver.save_screenshot(screenshot_path)\n  File \"/opt/hostedtoolcache/Python/3.9.20/x64/lib/python3.9/site-packages/selenium/webdriver/remote/webdriver.py\", line 829, in save_screenshot\n    return self.get_screenshot_as_file(filename)\n  File \"/opt/hostedtoolcache/Python/3.9.20/x64/lib/python3.9/site-packages/selenium/webdriver/remote/webdriver.py\", line 805, in get_screenshot_as_file\n    png = self.get_screenshot_as_png()\n  File \"/opt/hostedtoolcache/Python/3.9.20/x64/lib/python3.9/site-packages/selenium/webdriver/remote/webdriver.py\", line 839, in get_screenshot_as_png\n    return b64decode(self.get_screenshot_as_base64().encode(\"ascii\"))\n  File \"/opt/hostedtoolcache/Python/3.9.20/x64/lib/python3.9/site-packages/selenium/webdriver/remote/webdriver.py\", line 850, in get_screenshot_as_base64\n    return self.execute(Command.SCREENSHOT)[\"value\"]\n  File \"/opt/hostedtoolcache/Python/3.9.20/x64/lib/python3.9/site-packages/selenium/webdriver/remote/webdriver.py\", line 352, in execute\n    response = self.command_executor.execute(driver_command, params)\n  File \"/opt/hostedtoolcache/Python/3.9.20/x64/lib/python3.9/site-packages/selenium/webdriver/remote/remote_connection.py\", line 306, in execute\n    return self._request(command_info[0], url, body=data)\n  File \"/opt/hostedtoolcache/Python/3.9.20/x64/lib/python3.9/site-packages/selenium/webdriver/remote/remote_connection.py\", line 326, in _request\n    response = self._conn.request(method, url, body=body, headers=headers)\n  File \"/opt/hostedtoolcache/Python/3.9.20/x64/lib/python3.9/site-packages/urllib3/_request_methods.py\", line 135, in request\n    return self.request_encode_url(\n  File \"/opt/hostedtoolcache/Python/3.9.20/x64/lib/python3.9/site-packages/urllib3/_request_methods.py\", line 182, in request_encode_url\n    return self.urlopen(method, url, **extra_kw)\n  File \"/opt/hostedtoolcache/Python/3.9.20/x64/lib/python3.9/site-packages/urllib3/poolmanager.py\", line 443, in urlopen\n    response = conn.urlopen(method, u.request_uri, **kw)\n  File \"/opt/hostedtoolcache/Python/3.9.20/x64/lib/python3.9/site-packages/urllib3/connectionpool.py\", line 873, in urlopen\n    return self.urlopen(\n  File \"/opt/hostedtoolcache/Python/3.9.20/x64/lib/python3.9/site-packages/urllib3/connectionpool.py\", line 873, in urlopen\n    return self.urlopen(\n  File \"/opt/hostedtoolcache/Python/3.9.20/x64/lib/python3.9/site-packages/urllib3/connectionpool.py\", line 873, in urlopen\n    return self.urlopen(\n  File \"/opt/hostedtoolcache/Python/3.9.20/x64/lib/python3.9/site-packages/urllib3/connectionpool.py\", line 843, in urlopen\n    retries = retries.increment(\n  File \"/opt/hostedtoolcache/Python/3.9.20/x64/lib/python3.9/site-packages/urllib3/util/retry.py\", line 519, in increment\n    raise MaxRetryError(_pool, url, reason) from reason  # type: ignore[arg-type]\n","flaky":false,"newFailed":false,"newBroken":false,"newPassed":false,"retriesCount":0,"retriesStatusChange":false,"beforeStages":[],"testStage":{"status":"broken","statusMessage":"urllib3.exceptions.MaxRetryError: HTTPConnectionPool(host='localhost', port=48239): Max retries exceeded with url: /session/182ed2b93db7bbf3748c69ce5ef84bff/screenshot (Caused by NewConnectionError('<urllib3.connection.HTTPConnection object at 0x7f2823456af0>: Failed to establish a new connection: [Errno 111] Connection refused'))\n","statusTrace":"  File \"/opt/hostedtoolcache/Python/3.9.20/x64/lib/python3.9/site-packages/behave/runner.py\", line 545, in run_hook\n    self.hooks[name](context, *args)\n  File \"features/environment.py\", line 50, in after_step\n    context.driver.save_screenshot(screenshot_path)\n  File \"/opt/hostedtoolcache/Python/3.9.20/x64/lib/python3.9/site-packages/selenium/webdriver/remote/webdriver.py\", line 829, in save_screenshot\n    return self.get_screenshot_as_file(filename)\n  File \"/opt/hostedtoolcache/Python/3.9.20/x64/lib/python3.9/site-packages/selenium/webdriver/remote/webdriver.py\", line 805, in get_screenshot_as_file\n    png = self.get_screenshot_as_png()\n  File \"/opt/hostedtoolcache/Python/3.9.20/x64/lib/python3.9/site-packages/selenium/webdriver/remote/webdriver.py\", line 839, in get_screenshot_as_png\n    return b64decode(self.get_screenshot_as_base64().encode(\"ascii\"))\n  File \"/opt/hostedtoolcache/Python/3.9.20/x64/lib/python3.9/site-packages/selenium/webdriver/remote/webdriver.py\", line 850, in get_screenshot_as_base64\n    return self.execute(Command.SCREENSHOT)[\"value\"]\n  File \"/opt/hostedtoolcache/Python/3.9.20/x64/lib/python3.9/site-packages/selenium/webdriver/remote/webdriver.py\", line 352, in execute\n    response = self.command_executor.execute(driver_command, params)\n  File \"/opt/hostedtoolcache/Python/3.9.20/x64/lib/python3.9/site-packages/selenium/webdriver/remote/remote_connection.py\", line 306, in execute\n    return self._request(command_info[0], url, body=data)\n  File \"/opt/hostedtoolcache/Python/3.9.20/x64/lib/python3.9/site-packages/selenium/webdriver/remote/remote_connection.py\", line 326, in _request\n    response = self._conn.request(method, url, body=body, headers=headers)\n  File \"/opt/hostedtoolcache/Python/3.9.20/x64/lib/python3.9/site-packages/urllib3/_request_methods.py\", line 135, in request\n    return self.request_encode_url(\n  File \"/opt/hostedtoolcache/Python/3.9.20/x64/lib/python3.9/site-packages/urllib3/_request_methods.py\", line 182, in request_encode_url\n    return self.urlopen(method, url, **extra_kw)\n  File \"/opt/hostedtoolcache/Python/3.9.20/x64/lib/python3.9/site-packages/urllib3/poolmanager.py\", line 443, in urlopen\n    response = conn.urlopen(method, u.request_uri, **kw)\n  File \"/opt/hostedtoolcache/Python/3.9.20/x64/lib/python3.9/site-packages/urllib3/connectionpool.py\", line 873, in urlopen\n    return self.urlopen(\n  File \"/opt/hostedtoolcache/Python/3.9.20/x64/lib/python3.9/site-packages/urllib3/connectionpool.py\", line 873, in urlopen\n    return self.urlopen(\n  File \"/opt/hostedtoolcache/Python/3.9.20/x64/lib/python3.9/site-packages/urllib3/connectionpool.py\", line 873, in urlopen\n    return self.urlopen(\n  File \"/opt/hostedtoolcache/Python/3.9.20/x64/lib/python3.9/site-packages/urllib3/connectionpool.py\", line 843, in urlopen\n    retries = retries.increment(\n  File \"/opt/hostedtoolcache/Python/3.9.20/x64/lib/python3.9/site-packages/urllib3/util/retry.py\", line 519, in increment\n    raise MaxRetryError(_pool, url, reason) from reason  # type: ignore[arg-type]\n","steps":[{"name":"Given I am on the login page \"https://katalon-demo-cura.herokuapp.com/profile.php\"","time":{"start":1727098642140,"stop":1727098642762,"duration":622},"status":"passed","steps":[{"name":"User navigates to login page 'https://katalon-demo-cura.herokuapp.com/profile.php'","time":{"start":1727098642140,"stop":1727098642466,"duration":326},"status":"passed","steps":[],"attachments":[],"parameters":[{"name":"context","value":"<behave.runner.Context object at 0x7f2823d9e370>"},{"name":"url","value":"'https://katalon-demo-cura.herokuapp.com/profile.php'"}],"stepsCount":0,"attachmentsCount":0,"shouldDisplayMessage":false,"hasContent":true}],"attachments":[{"uid":"54fedcd4bda4fa44","name":"I am on the login page _https___katalon-demo-cura.herokuapp.com_profile.php__passed.png","source":"54fedcd4bda4fa44.png","type":"image/png","size":1227888}],"parameters":[],"stepsCount":1,"attachmentsCount":1,"shouldDisplayMessage":false,"hasContent":true},{"name":"When I enter a valid username \"John Doe\" and password \"ThisIsNotAPassword\"","time":{"start":1727098642762,"stop":1727098643122,"duration":360},"status":"passed","steps":[{"name":"User can enter username - \"'John Doe'\" and password - \"'ThisIsNotAPassword'\"","time":{"start":1727098642762,"stop":1727098642875,"duration":113},"status":"passed","steps":[],"attachments":[],"parameters":[{"name":"context","value":"<behave.runner.Context object at 0x7f2823d9e370>"},{"name":"username","value":"'John Doe'"},{"name":"password","value":"'ThisIsNotAPassword'"}],"stepsCount":0,"attachmentsCount":0,"shouldDisplayMessage":false,"hasContent":true}],"attachments":[{"uid":"9fecf96f30741eed","name":"I enter a valid username _John Doe_ and password _ThisIsNotAPassword__passed.png","source":"9fecf96f30741eed.png","type":"image/png","size":1227284}],"parameters":[],"stepsCount":1,"attachmentsCount":1,"shouldDisplayMessage":false,"hasContent":true},{"name":"And I click the login button","time":{"start":1727098643122,"stop":1727098643414,"duration":292},"status":"passed","steps":[{"name":"User can can click on login button","time":{"start":1727098643123,"stop":1727098643241,"duration":118},"status":"passed","steps":[],"attachments":[],"parameters":[{"name":"context","value":"<behave.runner.Context object at 0x7f2823d9e370>"}],"stepsCount":0,"attachmentsCount":0,"shouldDisplayMessage":false,"hasContent":true}],"attachments":[{"uid":"611b12020c4eff9a","name":"I click the login button_passed.png","source":"611b12020c4eff9a.png","type":"image/png","size":52486}],"parameters":[],"stepsCount":1,"attachmentsCount":1,"shouldDisplayMessage":false,"hasContent":true},{"name":"Then I should be redirected to the dashboard page","time":{"start":1727098643414,"stop":1727098643486,"duration":72},"status":"broken","statusMessage":"urllib3.exceptions.MaxRetryError: HTTPConnectionPool(host='localhost', port=48239): Max retries exceeded with url: /session/182ed2b93db7bbf3748c69ce5ef84bff/screenshot (Caused by NewConnectionError('<urllib3.connection.HTTPConnection object at 0x7f2823456af0>: Failed to establish a new connection: [Errno 111] Connection refused'))\n","statusTrace":"  File \"/opt/hostedtoolcache/Python/3.9.20/x64/lib/python3.9/site-packages/behave/runner.py\", line 545, in run_hook\n    self.hooks[name](context, *args)\n  File \"features/environment.py\", line 50, in after_step\n    context.driver.save_screenshot(screenshot_path)\n  File \"/opt/hostedtoolcache/Python/3.9.20/x64/lib/python3.9/site-packages/selenium/webdriver/remote/webdriver.py\", line 829, in save_screenshot\n    return self.get_screenshot_as_file(filename)\n  File \"/opt/hostedtoolcache/Python/3.9.20/x64/lib/python3.9/site-packages/selenium/webdriver/remote/webdriver.py\", line 805, in get_screenshot_as_file\n    png = self.get_screenshot_as_png()\n  File \"/opt/hostedtoolcache/Python/3.9.20/x64/lib/python3.9/site-packages/selenium/webdriver/remote/webdriver.py\", line 839, in get_screenshot_as_png\n    return b64decode(self.get_screenshot_as_base64().encode(\"ascii\"))\n  File \"/opt/hostedtoolcache/Python/3.9.20/x64/lib/python3.9/site-packages/selenium/webdriver/remote/webdriver.py\", line 850, in get_screenshot_as_base64\n    return self.execute(Command.SCREENSHOT)[\"value\"]\n  File \"/opt/hostedtoolcache/Python/3.9.20/x64/lib/python3.9/site-packages/selenium/webdriver/remote/webdriver.py\", line 352, in execute\n    response = self.command_executor.execute(driver_command, params)\n  File \"/opt/hostedtoolcache/Python/3.9.20/x64/lib/python3.9/site-packages/selenium/webdriver/remote/remote_connection.py\", line 306, in execute\n    return self._request(command_info[0], url, body=data)\n  File \"/opt/hostedtoolcache/Python/3.9.20/x64/lib/python3.9/site-packages/selenium/webdriver/remote/remote_connection.py\", line 326, in _request\n    response = self._conn.request(method, url, body=body, headers=headers)\n  File \"/opt/hostedtoolcache/Python/3.9.20/x64/lib/python3.9/site-packages/urllib3/_request_methods.py\", line 135, in request\n    return self.request_encode_url(\n  File \"/opt/hostedtoolcache/Python/3.9.20/x64/lib/python3.9/site-packages/urllib3/_request_methods.py\", line 182, in request_encode_url\n    return self.urlopen(method, url, **extra_kw)\n  File \"/opt/hostedtoolcache/Python/3.9.20/x64/lib/python3.9/site-packages/urllib3/poolmanager.py\", line 443, in urlopen\n    response = conn.urlopen(method, u.request_uri, **kw)\n  File \"/opt/hostedtoolcache/Python/3.9.20/x64/lib/python3.9/site-packages/urllib3/connectionpool.py\", line 873, in urlopen\n    return self.urlopen(\n  File \"/opt/hostedtoolcache/Python/3.9.20/x64/lib/python3.9/site-packages/urllib3/connectionpool.py\", line 873, in urlopen\n    return self.urlopen(\n  File \"/opt/hostedtoolcache/Python/3.9.20/x64/lib/python3.9/site-packages/urllib3/connectionpool.py\", line 873, in urlopen\n    return self.urlopen(\n  File \"/opt/hostedtoolcache/Python/3.9.20/x64/lib/python3.9/site-packages/urllib3/connectionpool.py\", line 843, in urlopen\n    retries = retries.increment(\n  File \"/opt/hostedtoolcache/Python/3.9.20/x64/lib/python3.9/site-packages/urllib3/util/retry.py\", line 519, in increment\n    raise MaxRetryError(_pool, url, reason) from reason  # type: ignore[arg-type]\n","steps":[{"name":"User login successfully and can see home page","time":{"start":1727098643414,"stop":1727098643482,"duration":68},"status":"passed","steps":[],"attachments":[],"parameters":[{"name":"context","value":"<behave.runner.Context object at 0x7f2823d9e370>"}],"stepsCount":0,"attachmentsCount":0,"shouldDisplayMessage":false,"hasContent":true}],"attachments":[],"parameters":[],"stepsCount":1,"attachmentsCount":0,"shouldDisplayMessage":true,"hasContent":true}],"attachments":[],"parameters":[],"stepsCount":8,"attachmentsCount":3,"shouldDisplayMessage":false,"hasContent":true},"afterStages":[],"labels":[{"name":"severity","value":"normal"},{"name":"feature","value":"User Login to katalon-demo-cura application"},{"name":"framework","value":"behave"},{"name":"language","value":"cpython3"},{"name":"resultFormat","value":"allure2"}],"parameters":[{"name":"password","value":"ThisIsNotAPassword"},{"name":"username","value":"John Doe"}],"links":[],"hidden":true,"retry":true,"extra":{"categories":[],"tags":[]},"source":"8c36b0655a7799a3.json","parameterValues":["ThisIsNotAPassword","John Doe"]}