{"uid":"e98e2c27c938197c","name":"Fail Test","fullName":"User Login to katalon-demo-cura application: Fail Test","historyId":"d3d39de6fc3cd407f5d66e2d343702f9","time":{"start":1727098643488,"stop":1727098643491,"duration":3},"status":"broken","statusMessage":"urllib3.exceptions.MaxRetryError: HTTPConnectionPool(host='localhost', port=48239): Max retries exceeded with url: /session/182ed2b93db7bbf3748c69ce5ef84bff/screenshot (Caused by NewConnectionError('<urllib3.connection.HTTPConnection object at 0x7f2822a62af0>: Failed to establish a new connection: [Errno 111] Connection refused'))\n","statusTrace":"  File \"/opt/hostedtoolcache/Python/3.9.20/x64/lib/python3.9/site-packages/behave/runner.py\", line 545, in run_hook\n    self.hooks[name](context, *args)\n  File \"features/environment.py\", line 44, in after_step\n    context.driver.save_screenshot(screenshot_path)\n  File \"/opt/hostedtoolcache/Python/3.9.20/x64/lib/python3.9/site-packages/selenium/webdriver/remote/webdriver.py\", line 829, in save_screenshot\n    return self.get_screenshot_as_file(filename)\n  File \"/opt/hostedtoolcache/Python/3.9.20/x64/lib/python3.9/site-packages/selenium/webdriver/remote/webdriver.py\", line 805, in get_screenshot_as_file\n    png = self.get_screenshot_as_png()\n  File \"/opt/hostedtoolcache/Python/3.9.20/x64/lib/python3.9/site-packages/selenium/webdriver/remote/webdriver.py\", line 839, in get_screenshot_as_png\n    return b64decode(self.get_screenshot_as_base64().encode(\"ascii\"))\n  File \"/opt/hostedtoolcache/Python/3.9.20/x64/lib/python3.9/site-packages/selenium/webdriver/remote/webdriver.py\", line 850, in get_screenshot_as_base64\n    return self.execute(Command.SCREENSHOT)[\"value\"]\n  File \"/opt/hostedtoolcache/Python/3.9.20/x64/lib/python3.9/site-packages/selenium/webdriver/remote/webdriver.py\", line 352, in execute\n    response = self.command_executor.execute(driver_command, params)\n  File \"/opt/hostedtoolcache/Python/3.9.20/x64/lib/python3.9/site-packages/selenium/webdriver/remote/remote_connection.py\", line 306, in execute\n    return self._request(command_info[0], url, body=data)\n  File \"/opt/hostedtoolcache/Python/3.9.20/x64/lib/python3.9/site-packages/selenium/webdriver/remote/remote_connection.py\", line 326, in _request\n    response = self._conn.request(method, url, body=body, headers=headers)\n  File \"/opt/hostedtoolcache/Python/3.9.20/x64/lib/python3.9/site-packages/urllib3/_request_methods.py\", line 135, in request\n    return self.request_encode_url(\n  File \"/opt/hostedtoolcache/Python/3.9.20/x64/lib/python3.9/site-packages/urllib3/_request_methods.py\", line 182, in request_encode_url\n    return self.urlopen(method, url, **extra_kw)\n  File \"/opt/hostedtoolcache/Python/3.9.20/x64/lib/python3.9/site-packages/urllib3/poolmanager.py\", line 443, in urlopen\n    response = conn.urlopen(method, u.request_uri, **kw)\n  File \"/opt/hostedtoolcache/Python/3.9.20/x64/lib/python3.9/site-packages/urllib3/connectionpool.py\", line 873, in urlopen\n    return self.urlopen(\n  File \"/opt/hostedtoolcache/Python/3.9.20/x64/lib/python3.9/site-packages/urllib3/connectionpool.py\", line 873, in urlopen\n    return self.urlopen(\n  File \"/opt/hostedtoolcache/Python/3.9.20/x64/lib/python3.9/site-packages/urllib3/connectionpool.py\", line 873, in urlopen\n    return self.urlopen(\n  File \"/opt/hostedtoolcache/Python/3.9.20/x64/lib/python3.9/site-packages/urllib3/connectionpool.py\", line 843, in urlopen\n    retries = retries.increment(\n  File \"/opt/hostedtoolcache/Python/3.9.20/x64/lib/python3.9/site-packages/urllib3/util/retry.py\", line 519, in increment\n    raise MaxRetryError(_pool, url, reason) from reason  # type: ignore[arg-type]\n","flaky":false,"newFailed":false,"newBroken":false,"newPassed":false,"retriesCount":0,"retriesStatusChange":false,"beforeStages":[],"testStage":{"status":"broken","statusMessage":"urllib3.exceptions.MaxRetryError: HTTPConnectionPool(host='localhost', port=48239): Max retries exceeded with url: /session/182ed2b93db7bbf3748c69ce5ef84bff/screenshot (Caused by NewConnectionError('<urllib3.connection.HTTPConnection object at 0x7f2822a62af0>: Failed to establish a new connection: [Errno 111] Connection refused'))\n","statusTrace":"  File \"/opt/hostedtoolcache/Python/3.9.20/x64/lib/python3.9/site-packages/behave/runner.py\", line 545, in run_hook\n    self.hooks[name](context, *args)\n  File \"features/environment.py\", line 44, in after_step\n    context.driver.save_screenshot(screenshot_path)\n  File \"/opt/hostedtoolcache/Python/3.9.20/x64/lib/python3.9/site-packages/selenium/webdriver/remote/webdriver.py\", line 829, in save_screenshot\n    return self.get_screenshot_as_file(filename)\n  File \"/opt/hostedtoolcache/Python/3.9.20/x64/lib/python3.9/site-packages/selenium/webdriver/remote/webdriver.py\", line 805, in get_screenshot_as_file\n    png = self.get_screenshot_as_png()\n  File \"/opt/hostedtoolcache/Python/3.9.20/x64/lib/python3.9/site-packages/selenium/webdriver/remote/webdriver.py\", line 839, in get_screenshot_as_png\n    return b64decode(self.get_screenshot_as_base64().encode(\"ascii\"))\n  File \"/opt/hostedtoolcache/Python/3.9.20/x64/lib/python3.9/site-packages/selenium/webdriver/remote/webdriver.py\", line 850, in get_screenshot_as_base64\n    return self.execute(Command.SCREENSHOT)[\"value\"]\n  File \"/opt/hostedtoolcache/Python/3.9.20/x64/lib/python3.9/site-packages/selenium/webdriver/remote/webdriver.py\", line 352, in execute\n    response = self.command_executor.execute(driver_command, params)\n  File \"/opt/hostedtoolcache/Python/3.9.20/x64/lib/python3.9/site-packages/selenium/webdriver/remote/remote_connection.py\", line 306, in execute\n    return self._request(command_info[0], url, body=data)\n  File \"/opt/hostedtoolcache/Python/3.9.20/x64/lib/python3.9/site-packages/selenium/webdriver/remote/remote_connection.py\", line 326, in _request\n    response = self._conn.request(method, url, body=body, headers=headers)\n  File \"/opt/hostedtoolcache/Python/3.9.20/x64/lib/python3.9/site-packages/urllib3/_request_methods.py\", line 135, in request\n    return self.request_encode_url(\n  File \"/opt/hostedtoolcache/Python/3.9.20/x64/lib/python3.9/site-packages/urllib3/_request_methods.py\", line 182, in request_encode_url\n    return self.urlopen(method, url, **extra_kw)\n  File \"/opt/hostedtoolcache/Python/3.9.20/x64/lib/python3.9/site-packages/urllib3/poolmanager.py\", line 443, in urlopen\n    response = conn.urlopen(method, u.request_uri, **kw)\n  File \"/opt/hostedtoolcache/Python/3.9.20/x64/lib/python3.9/site-packages/urllib3/connectionpool.py\", line 873, in urlopen\n    return self.urlopen(\n  File \"/opt/hostedtoolcache/Python/3.9.20/x64/lib/python3.9/site-packages/urllib3/connectionpool.py\", line 873, in urlopen\n    return self.urlopen(\n  File \"/opt/hostedtoolcache/Python/3.9.20/x64/lib/python3.9/site-packages/urllib3/connectionpool.py\", line 873, in urlopen\n    return self.urlopen(\n  File \"/opt/hostedtoolcache/Python/3.9.20/x64/lib/python3.9/site-packages/urllib3/connectionpool.py\", line 843, in urlopen\n    retries = retries.increment(\n  File \"/opt/hostedtoolcache/Python/3.9.20/x64/lib/python3.9/site-packages/urllib3/util/retry.py\", line 519, in increment\n    raise MaxRetryError(_pool, url, reason) from reason  # type: ignore[arg-type]\n","steps":[{"name":"Given I am failure","time":{"start":1727098643488,"stop":1727098643490,"duration":2},"status":"broken","statusMessage":"urllib3.exceptions.MaxRetryError: HTTPConnectionPool(host='localhost', port=48239): Max retries exceeded with url: /session/182ed2b93db7bbf3748c69ce5ef84bff/screenshot (Caused by NewConnectionError('<urllib3.connection.HTTPConnection object at 0x7f2822a62af0>: Failed to establish a new connection: [Errno 111] Connection refused'))\n","statusTrace":"  File \"/opt/hostedtoolcache/Python/3.9.20/x64/lib/python3.9/site-packages/behave/runner.py\", line 545, in run_hook\n    self.hooks[name](context, *args)\n  File \"features/environment.py\", line 44, in after_step\n    context.driver.save_screenshot(screenshot_path)\n  File \"/opt/hostedtoolcache/Python/3.9.20/x64/lib/python3.9/site-packages/selenium/webdriver/remote/webdriver.py\", line 829, in save_screenshot\n    return self.get_screenshot_as_file(filename)\n  File \"/opt/hostedtoolcache/Python/3.9.20/x64/lib/python3.9/site-packages/selenium/webdriver/remote/webdriver.py\", line 805, in get_screenshot_as_file\n    png = self.get_screenshot_as_png()\n  File \"/opt/hostedtoolcache/Python/3.9.20/x64/lib/python3.9/site-packages/selenium/webdriver/remote/webdriver.py\", line 839, in get_screenshot_as_png\n    return b64decode(self.get_screenshot_as_base64().encode(\"ascii\"))\n  File \"/opt/hostedtoolcache/Python/3.9.20/x64/lib/python3.9/site-packages/selenium/webdriver/remote/webdriver.py\", line 850, in get_screenshot_as_base64\n    return self.execute(Command.SCREENSHOT)[\"value\"]\n  File \"/opt/hostedtoolcache/Python/3.9.20/x64/lib/python3.9/site-packages/selenium/webdriver/remote/webdriver.py\", line 352, in execute\n    response = self.command_executor.execute(driver_command, params)\n  File \"/opt/hostedtoolcache/Python/3.9.20/x64/lib/python3.9/site-packages/selenium/webdriver/remote/remote_connection.py\", line 306, in execute\n    return self._request(command_info[0], url, body=data)\n  File \"/opt/hostedtoolcache/Python/3.9.20/x64/lib/python3.9/site-packages/selenium/webdriver/remote/remote_connection.py\", line 326, in _request\n    response = self._conn.request(method, url, body=body, headers=headers)\n  File \"/opt/hostedtoolcache/Python/3.9.20/x64/lib/python3.9/site-packages/urllib3/_request_methods.py\", line 135, in request\n    return self.request_encode_url(\n  File \"/opt/hostedtoolcache/Python/3.9.20/x64/lib/python3.9/site-packages/urllib3/_request_methods.py\", line 182, in request_encode_url\n    return self.urlopen(method, url, **extra_kw)\n  File \"/opt/hostedtoolcache/Python/3.9.20/x64/lib/python3.9/site-packages/urllib3/poolmanager.py\", line 443, in urlopen\n    response = conn.urlopen(method, u.request_uri, **kw)\n  File \"/opt/hostedtoolcache/Python/3.9.20/x64/lib/python3.9/site-packages/urllib3/connectionpool.py\", line 873, in urlopen\n    return self.urlopen(\n  File \"/opt/hostedtoolcache/Python/3.9.20/x64/lib/python3.9/site-packages/urllib3/connectionpool.py\", line 873, in urlopen\n    return self.urlopen(\n  File \"/opt/hostedtoolcache/Python/3.9.20/x64/lib/python3.9/site-packages/urllib3/connectionpool.py\", line 873, in urlopen\n    return self.urlopen(\n  File \"/opt/hostedtoolcache/Python/3.9.20/x64/lib/python3.9/site-packages/urllib3/connectionpool.py\", line 843, in urlopen\n    retries = retries.increment(\n  File \"/opt/hostedtoolcache/Python/3.9.20/x64/lib/python3.9/site-packages/urllib3/util/retry.py\", line 519, in increment\n    raise MaxRetryError(_pool, url, reason) from reason  # type: ignore[arg-type]\n","steps":[],"attachments":[],"parameters":[],"stepsCount":0,"attachmentsCount":0,"shouldDisplayMessage":true,"hasContent":true}],"attachments":[],"parameters":[],"stepsCount":1,"attachmentsCount":0,"shouldDisplayMessage":false,"hasContent":true},"afterStages":[],"labels":[{"name":"severity","value":"normal"},{"name":"feature","value":"User Login to katalon-demo-cura application"},{"name":"framework","value":"behave"},{"name":"language","value":"cpython3"},{"name":"resultFormat","value":"allure2"}],"parameters":[],"links":[],"hidden":true,"retry":true,"extra":{"categories":[],"tags":[]},"source":"e98e2c27c938197c.json","parameterValues":[]}