{"name": "Fail This Test For Report -- @1.1 ", "status": "broken", "statusDetails": {"message": "urllib3.exceptions.MaxRetryError: HTTPConnectionPool(host='localhost', port=37141): Max retries exceeded with url: /session/fc8eb2ec948741490d5d64b192f74f73/url (Caused by NewConnectionError('<urllib3.connection.HTTPConnection object at 0x7f751ac045b0>: Failed to establish a new connection: [Errno 111] Connection refused'))\n", "trace": "  File \"/opt/hostedtoolcache/Python/3.9.20/x64/lib/python3.9/site-packages/behave/model.py\", line 1329, in run\n    match.run(runner.context)\n  File \"/opt/hostedtoolcache/Python/3.9.20/x64/lib/python3.9/site-packages/behave/matchers.py\", line 98, in run\n    self.func(context, *args, **kwargs)\n  File \"/opt/hostedtoolcache/Python/3.9.20/x64/lib/python3.9/site-packages/allure_commons/_allure.py\", line 192, in impl\n    return func(*a, **kw)\n  File \"features/steps/login_steps.py\", line 9, in step_given_on_login_page\n    context.driver.get(url)\n  File \"/opt/hostedtoolcache/Python/3.9.20/x64/lib/python3.9/site-packages/selenium/webdriver/remote/webdriver.py\", line 363, in get\n    self.execute(Command.GET, {\"url\": url})\n  File \"/opt/hostedtoolcache/Python/3.9.20/x64/lib/python3.9/site-packages/selenium/webdriver/remote/webdriver.py\", line 352, in execute\n    response = self.command_executor.execute(driver_command, params)\n  File \"/opt/hostedtoolcache/Python/3.9.20/x64/lib/python3.9/site-packages/selenium/webdriver/remote/remote_connection.py\", line 306, in execute\n    return self._request(command_info[0], url, body=data)\n  File \"/opt/hostedtoolcache/Python/3.9.20/x64/lib/python3.9/site-packages/selenium/webdriver/remote/remote_connection.py\", line 326, in _request\n    response = self._conn.request(method, url, body=body, headers=headers)\n  File \"/opt/hostedtoolcache/Python/3.9.20/x64/lib/python3.9/site-packages/urllib3/_request_methods.py\", line 143, in request\n    return self.request_encode_body(\n  File \"/opt/hostedtoolcache/Python/3.9.20/x64/lib/python3.9/site-packages/urllib3/_request_methods.py\", line 278, in request_encode_body\n    return self.urlopen(method, url, **extra_kw)\n  File \"/opt/hostedtoolcache/Python/3.9.20/x64/lib/python3.9/site-packages/urllib3/poolmanager.py\", line 443, in urlopen\n    response = conn.urlopen(method, u.request_uri, **kw)\n  File \"/opt/hostedtoolcache/Python/3.9.20/x64/lib/python3.9/site-packages/urllib3/connectionpool.py\", line 873, in urlopen\n    return self.urlopen(\n  File \"/opt/hostedtoolcache/Python/3.9.20/x64/lib/python3.9/site-packages/urllib3/connectionpool.py\", line 873, in urlopen\n    return self.urlopen(\n  File \"/opt/hostedtoolcache/Python/3.9.20/x64/lib/python3.9/site-packages/urllib3/connectionpool.py\", line 873, in urlopen\n    return self.urlopen(\n  File \"/opt/hostedtoolcache/Python/3.9.20/x64/lib/python3.9/site-packages/urllib3/connectionpool.py\", line 843, in urlopen\n    retries = retries.increment(\n  File \"/opt/hostedtoolcache/Python/3.9.20/x64/lib/python3.9/site-packages/urllib3/util/retry.py\", line 519, in increment\n    raise MaxRetryError(_pool, url, reason) from reason  # type: ignore[arg-type]\n"}, "steps": [{"name": "Given I am on the login page \"https://katalon-demo-cura.herokuapp.com/profile.php\"", "status": "broken", "statusDetails": {"message": "urllib3.exceptions.MaxRetryError: HTTPConnectionPool(host='localhost', port=37141): Max retries exceeded with url: /session/fc8eb2ec948741490d5d64b192f74f73/url (Caused by NewConnectionError('<urllib3.connection.HTTPConnection object at 0x7f751ac045b0>: Failed to establish a new connection: [Errno 111] Connection refused'))\n", "trace": "  File \"/opt/hostedtoolcache/Python/3.9.20/x64/lib/python3.9/site-packages/behave/model.py\", line 1329, in run\n    match.run(runner.context)\n  File \"/opt/hostedtoolcache/Python/3.9.20/x64/lib/python3.9/site-packages/behave/matchers.py\", line 98, in run\n    self.func(context, *args, **kwargs)\n  File \"/opt/hostedtoolcache/Python/3.9.20/x64/lib/python3.9/site-packages/allure_commons/_allure.py\", line 192, in impl\n    return func(*a, **kw)\n  File \"features/steps/login_steps.py\", line 9, in step_given_on_login_page\n    context.driver.get(url)\n  File \"/opt/hostedtoolcache/Python/3.9.20/x64/lib/python3.9/site-packages/selenium/webdriver/remote/webdriver.py\", line 363, in get\n    self.execute(Command.GET, {\"url\": url})\n  File \"/opt/hostedtoolcache/Python/3.9.20/x64/lib/python3.9/site-packages/selenium/webdriver/remote/webdriver.py\", line 352, in execute\n    response = self.command_executor.execute(driver_command, params)\n  File \"/opt/hostedtoolcache/Python/3.9.20/x64/lib/python3.9/site-packages/selenium/webdriver/remote/remote_connection.py\", line 306, in execute\n    return self._request(command_info[0], url, body=data)\n  File \"/opt/hostedtoolcache/Python/3.9.20/x64/lib/python3.9/site-packages/selenium/webdriver/remote/remote_connection.py\", line 326, in _request\n    response = self._conn.request(method, url, body=body, headers=headers)\n  File \"/opt/hostedtoolcache/Python/3.9.20/x64/lib/python3.9/site-packages/urllib3/_request_methods.py\", line 143, in request\n    return self.request_encode_body(\n  File \"/opt/hostedtoolcache/Python/3.9.20/x64/lib/python3.9/site-packages/urllib3/_request_methods.py\", line 278, in request_encode_body\n    return self.urlopen(method, url, **extra_kw)\n  File \"/opt/hostedtoolcache/Python/3.9.20/x64/lib/python3.9/site-packages/urllib3/poolmanager.py\", line 443, in urlopen\n    response = conn.urlopen(method, u.request_uri, **kw)\n  File \"/opt/hostedtoolcache/Python/3.9.20/x64/lib/python3.9/site-packages/urllib3/connectionpool.py\", line 873, in urlopen\n    return self.urlopen(\n  File \"/opt/hostedtoolcache/Python/3.9.20/x64/lib/python3.9/site-packages/urllib3/connectionpool.py\", line 873, in urlopen\n    return self.urlopen(\n  File \"/opt/hostedtoolcache/Python/3.9.20/x64/lib/python3.9/site-packages/urllib3/connectionpool.py\", line 873, in urlopen\n    return self.urlopen(\n  File \"/opt/hostedtoolcache/Python/3.9.20/x64/lib/python3.9/site-packages/urllib3/connectionpool.py\", line 843, in urlopen\n    retries = retries.increment(\n  File \"/opt/hostedtoolcache/Python/3.9.20/x64/lib/python3.9/site-packages/urllib3/util/retry.py\", line 519, in increment\n    raise MaxRetryError(_pool, url, reason) from reason  # type: ignore[arg-type]\n"}, "steps": [{"name": "User navigates to login page 'https://katalon-demo-cura.herokuapp.com/profile.php'", "status": "broken", "statusDetails": {"message": "urllib3.exceptions.MaxRetryError: HTTPConnectionPool(host='localhost', port=37141): Max retries exceeded with url: /session/fc8eb2ec948741490d5d64b192f74f73/url (Caused by NewConnectionError('<urllib3.connection.HTTPConnection object at 0x7f751ac045b0>: Failed to establish a new connection: [Errno 111] Connection refused'))\n", "trace": "  File \"/opt/hostedtoolcache/Python/3.9.20/x64/lib/python3.9/site-packages/allure_commons/_allure.py\", line 192, in impl\n    return func(*a, **kw)\n  File \"features/steps/login_steps.py\", line 9, in step_given_on_login_page\n    context.driver.get(url)\n  File \"/opt/hostedtoolcache/Python/3.9.20/x64/lib/python3.9/site-packages/selenium/webdriver/remote/webdriver.py\", line 363, in get\n    self.execute(Command.GET, {\"url\": url})\n  File \"/opt/hostedtoolcache/Python/3.9.20/x64/lib/python3.9/site-packages/selenium/webdriver/remote/webdriver.py\", line 352, in execute\n    response = self.command_executor.execute(driver_command, params)\n  File \"/opt/hostedtoolcache/Python/3.9.20/x64/lib/python3.9/site-packages/selenium/webdriver/remote/remote_connection.py\", line 306, in execute\n    return self._request(command_info[0], url, body=data)\n  File \"/opt/hostedtoolcache/Python/3.9.20/x64/lib/python3.9/site-packages/selenium/webdriver/remote/remote_connection.py\", line 326, in _request\n    response = self._conn.request(method, url, body=body, headers=headers)\n  File \"/opt/hostedtoolcache/Python/3.9.20/x64/lib/python3.9/site-packages/urllib3/_request_methods.py\", line 143, in request\n    return self.request_encode_body(\n  File \"/opt/hostedtoolcache/Python/3.9.20/x64/lib/python3.9/site-packages/urllib3/_request_methods.py\", line 278, in request_encode_body\n    return self.urlopen(method, url, **extra_kw)\n  File \"/opt/hostedtoolcache/Python/3.9.20/x64/lib/python3.9/site-packages/urllib3/poolmanager.py\", line 443, in urlopen\n    response = conn.urlopen(method, u.request_uri, **kw)\n  File \"/opt/hostedtoolcache/Python/3.9.20/x64/lib/python3.9/site-packages/urllib3/connectionpool.py\", line 873, in urlopen\n    return self.urlopen(\n  File \"/opt/hostedtoolcache/Python/3.9.20/x64/lib/python3.9/site-packages/urllib3/connectionpool.py\", line 873, in urlopen\n    return self.urlopen(\n  File \"/opt/hostedtoolcache/Python/3.9.20/x64/lib/python3.9/site-packages/urllib3/connectionpool.py\", line 873, in urlopen\n    return self.urlopen(\n  File \"/opt/hostedtoolcache/Python/3.9.20/x64/lib/python3.9/site-packages/urllib3/connectionpool.py\", line 843, in urlopen\n    retries = retries.increment(\n  File \"/opt/hostedtoolcache/Python/3.9.20/x64/lib/python3.9/site-packages/urllib3/util/retry.py\", line 519, in increment\n    raise MaxRetryError(_pool, url, reason) from reason  # type: ignore[arg-type]\n"}, "parameters": [{"name": "context", "value": "<behave.runner.Context object at 0x7f751b9772e0>"}, {"name": "url", "value": "'https://katalon-demo-cura.herokuapp.com/profile.php'"}], "start": 1727121505121, "stop": 1727121505123}], "start": 1727121505121, "stop": 1727121505127}, {"name": "When I enter a valid username \"John Doe\" and password \"WrongPassword\"", "status": "skipped", "start": 1727121505128, "stop": 1727121505128}, {"name": "And I click the login button", "status": "skipped", "start": 1727121505128, "stop": 1727121505128}, {"name": "Then I should be redirected to the dashboard page", "status": "skipped", "start": 1727121505128, "stop": 1727121505128}], "parameters": [{"name": "username", "value": "John Doe"}, {"name": "password", "value": "WrongPassword"}], "start": 1727121505120, "stop": 1727121505128, "uuid": "6fba74a4-3e12-4756-a990-9e7d74353af8", "historyId": "7d2e96ee84eb5b3762ae71ee50e89fb0", "fullName": "User Login to katalon-demo-cura application: Fail This Test For Report", "labels": [{"name": "severity", "value": "normal"}, {"name": "tag", "value": "positive"}, {"name": "tag", "value": "severity.minor"}, {"name": "tag", "value": "ui"}, {"name": "feature", "value": "User Login to katalon-demo-cura application"}, {"name": "framework", "value": "behave"}, {"name": "language", "value": "cpython3"}]}