{"name": "Fail Test", "status": "broken", "statusDetails": {"message": "urllib3.exceptions.MaxRetryError: HTTPConnectionPool(host='localhost', port=48239): Max retries exceeded with url: /session/182ed2b93db7bbf3748c69ce5ef84bff/screenshot (Caused by NewConnectionError('<urllib3.connection.HTTPConnection object at 0x7f2822a62af0>: Failed to establish a new connection: [Errno 111] Connection refused'))\n", "trace": "  File \"/opt/hostedtoolcache/Python/3.9.20/x64/lib/python3.9/site-packages/behave/runner.py\", line 545, in run_hook\n    self.hooks[name](context, *args)\n  File \"features/environment.py\", line 44, in after_step\n    context.driver.save_screenshot(screenshot_path)\n  File \"/opt/hostedtoolcache/Python/3.9.20/x64/lib/python3.9/site-packages/selenium/webdriver/remote/webdriver.py\", line 829, in save_screenshot\n    return self.get_screenshot_as_file(filename)\n  File \"/opt/hostedtoolcache/Python/3.9.20/x64/lib/python3.9/site-packages/selenium/webdriver/remote/webdriver.py\", line 805, in get_screenshot_as_file\n    png = self.get_screenshot_as_png()\n  File \"/opt/hostedtoolcache/Python/3.9.20/x64/lib/python3.9/site-packages/selenium/webdriver/remote/webdriver.py\", line 839, in get_screenshot_as_png\n    return b64decode(self.get_screenshot_as_base64().encode(\"ascii\"))\n  File \"/opt/hostedtoolcache/Python/3.9.20/x64/lib/python3.9/site-packages/selenium/webdriver/remote/webdriver.py\", line 850, in get_screenshot_as_base64\n    return self.execute(Command.SCREENSHOT)[\"value\"]\n  File \"/opt/hostedtoolcache/Python/3.9.20/x64/lib/python3.9/site-packages/selenium/webdriver/remote/webdriver.py\", line 352, in execute\n    response = self.command_executor.execute(driver_command, params)\n  File \"/opt/hostedtoolcache/Python/3.9.20/x64/lib/python3.9/site-packages/selenium/webdriver/remote/remote_connection.py\", line 306, in execute\n    return self._request(command_info[0], url, body=data)\n  File \"/opt/hostedtoolcache/Python/3.9.20/x64/lib/python3.9/site-packages/selenium/webdriver/remote/remote_connection.py\", line 326, in _request\n    response = self._conn.request(method, url, body=body, headers=headers)\n  File \"/opt/hostedtoolcache/Python/3.9.20/x64/lib/python3.9/site-packages/urllib3/_request_methods.py\", line 135, in request\n    return self.request_encode_url(\n  File \"/opt/hostedtoolcache/Python/3.9.20/x64/lib/python3.9/site-packages/urllib3/_request_methods.py\", line 182, in request_encode_url\n    return self.urlopen(method, url, **extra_kw)\n  File \"/opt/hostedtoolcache/Python/3.9.20/x64/lib/python3.9/site-packages/urllib3/poolmanager.py\", line 443, in urlopen\n    response = conn.urlopen(method, u.request_uri, **kw)\n  File \"/opt/hostedtoolcache/Python/3.9.20/x64/lib/python3.9/site-packages/urllib3/connectionpool.py\", line 873, in urlopen\n    return self.urlopen(\n  File \"/opt/hostedtoolcache/Python/3.9.20/x64/lib/python3.9/site-packages/urllib3/connectionpool.py\", line 873, in urlopen\n    return self.urlopen(\n  File \"/opt/hostedtoolcache/Python/3.9.20/x64/lib/python3.9/site-packages/urllib3/connectionpool.py\", line 873, in urlopen\n    return self.urlopen(\n  File \"/opt/hostedtoolcache/Python/3.9.20/x64/lib/python3.9/site-packages/urllib3/connectionpool.py\", line 843, in urlopen\n    retries = retries.increment(\n  File \"/opt/hostedtoolcache/Python/3.9.20/x64/lib/python3.9/site-packages/urllib3/util/retry.py\", line 519, in increment\n    raise MaxRetryError(_pool, url, reason) from reason  # type: ignore[arg-type]\n"}, "steps": [{"name": "Given I am failure", "status": "broken", "statusDetails": {"message": "urllib3.exceptions.MaxRetryError: HTTPConnectionPool(host='localhost', port=48239): Max retries exceeded with url: /session/182ed2b93db7bbf3748c69ce5ef84bff/screenshot (Caused by NewConnectionError('<urllib3.connection.HTTPConnection object at 0x7f2822a62af0>: Failed to establish a new connection: [Errno 111] Connection refused'))\n", "trace": "  File \"/opt/hostedtoolcache/Python/3.9.20/x64/lib/python3.9/site-packages/behave/runner.py\", line 545, in run_hook\n    self.hooks[name](context, *args)\n  File \"features/environment.py\", line 44, in after_step\n    context.driver.save_screenshot(screenshot_path)\n  File \"/opt/hostedtoolcache/Python/3.9.20/x64/lib/python3.9/site-packages/selenium/webdriver/remote/webdriver.py\", line 829, in save_screenshot\n    return self.get_screenshot_as_file(filename)\n  File \"/opt/hostedtoolcache/Python/3.9.20/x64/lib/python3.9/site-packages/selenium/webdriver/remote/webdriver.py\", line 805, in get_screenshot_as_file\n    png = self.get_screenshot_as_png()\n  File \"/opt/hostedtoolcache/Python/3.9.20/x64/lib/python3.9/site-packages/selenium/webdriver/remote/webdriver.py\", line 839, in get_screenshot_as_png\n    return b64decode(self.get_screenshot_as_base64().encode(\"ascii\"))\n  File \"/opt/hostedtoolcache/Python/3.9.20/x64/lib/python3.9/site-packages/selenium/webdriver/remote/webdriver.py\", line 850, in get_screenshot_as_base64\n    return self.execute(Command.SCREENSHOT)[\"value\"]\n  File \"/opt/hostedtoolcache/Python/3.9.20/x64/lib/python3.9/site-packages/selenium/webdriver/remote/webdriver.py\", line 352, in execute\n    response = self.command_executor.execute(driver_command, params)\n  File \"/opt/hostedtoolcache/Python/3.9.20/x64/lib/python3.9/site-packages/selenium/webdriver/remote/remote_connection.py\", line 306, in execute\n    return self._request(command_info[0], url, body=data)\n  File \"/opt/hostedtoolcache/Python/3.9.20/x64/lib/python3.9/site-packages/selenium/webdriver/remote/remote_connection.py\", line 326, in _request\n    response = self._conn.request(method, url, body=body, headers=headers)\n  File \"/opt/hostedtoolcache/Python/3.9.20/x64/lib/python3.9/site-packages/urllib3/_request_methods.py\", line 135, in request\n    return self.request_encode_url(\n  File \"/opt/hostedtoolcache/Python/3.9.20/x64/lib/python3.9/site-packages/urllib3/_request_methods.py\", line 182, in request_encode_url\n    return self.urlopen(method, url, **extra_kw)\n  File \"/opt/hostedtoolcache/Python/3.9.20/x64/lib/python3.9/site-packages/urllib3/poolmanager.py\", line 443, in urlopen\n    response = conn.urlopen(method, u.request_uri, **kw)\n  File \"/opt/hostedtoolcache/Python/3.9.20/x64/lib/python3.9/site-packages/urllib3/connectionpool.py\", line 873, in urlopen\n    return self.urlopen(\n  File \"/opt/hostedtoolcache/Python/3.9.20/x64/lib/python3.9/site-packages/urllib3/connectionpool.py\", line 873, in urlopen\n    return self.urlopen(\n  File \"/opt/hostedtoolcache/Python/3.9.20/x64/lib/python3.9/site-packages/urllib3/connectionpool.py\", line 873, in urlopen\n    return self.urlopen(\n  File \"/opt/hostedtoolcache/Python/3.9.20/x64/lib/python3.9/site-packages/urllib3/connectionpool.py\", line 843, in urlopen\n    retries = retries.increment(\n  File \"/opt/hostedtoolcache/Python/3.9.20/x64/lib/python3.9/site-packages/urllib3/util/retry.py\", line 519, in increment\n    raise MaxRetryError(_pool, url, reason) from reason  # type: ignore[arg-type]\n"}, "start": 1727098643488, "stop": 1727098643490}], "start": 1727098643488, "stop": 1727098643491, "uuid": "548a1b01-5350-4c27-a85b-f88bef215ea1", "historyId": "d3d39de6fc3cd407f5d66e2d343702f9", "fullName": "User Login to katalon-demo-cura application: Fail Test", "labels": [{"name": "severity", "value": "normal"}, {"name": "feature", "value": "User Login to katalon-demo-cura application"}, {"name": "framework", "value": "behave"}, {"name": "language", "value": "cpython3"}]}